<?xml version="1.0"?>
<robot xmlns:xacro="http://wiki.ros.org/xacro">


<!-- XACRO-MACRO of PANDA ROBOT: -->
 <xacro:macro name="panda" params="parent prefix *origin">

    <!-- Base Joint to fix the Panda Model to the world-->
    <joint name="base_joint" type="fixed">
      <xacro:insert_block name="origin" />
      <parent link="${parent}"/>
      <child link="${prefix}panda_link0" />
    </joint>


    <!-- ***** PANDA ROBOT .urdf SERIAL CHAIN ***** -->

    <!-- panda_link0 -->
    <link name="${prefix}panda_link0">
      <inertial>
        <mass value="2.814271300104062"/>
        <origin rpy="0 0 0" xyz="-0.025566 -2.88e-05 0.057332"/>
        <inertia ixx="0.0075390636364814695" ixy="-1.5053124574783335e-05" ixz="-0.0012144328835738973" iyy="0.010508017427382959" iyz="1.0434803501032979e-05" izz="0.009864933638708275"/>
      </inertial>
      <visual>
        <origin rpy="0 0 0" xyz="0 0 0"/>
        <geometry>
          <mesh filename="file://$(find panda_urdf)/meshes/visual/link0.dae"/>
        </geometry>
      </visual>
      <collision>
        <origin rpy="0 0 0" xyz="0 0 0"/>
        <geometry>
          <mesh filename="file://$(find panda_urdf)/meshes/collision/link0.stl"/>
        </geometry>
      </collision>
    </link>

    <!-- panda_link1 -->
    <link name="${prefix}panda_link1">
      <inertial>
        <mass value="2.6433170427227215"/>
        <origin rpy="0 0 0" xyz="-3.72212e-09  -0.0324958 -0.0675818"/>
        <inertia ixx="0.017405076982879724" ixy="-8.687986369621078e-09" ixz="-1.6277819062920423e-08" iyy="0.015352077935781732" iyz="0.004510855959102245" izz="0.005987891663073857"/>
      </inertial>
      <visual>
        <origin rpy="0 0 0" xyz="0 0 0"/>
        <geometry>
          <mesh filename="file://$(find panda_urdf)/meshes/visual/link1.dae"/>
        </geometry>
      </visual>
      <collision>
        <origin rpy="0 0 0" xyz="0 0 0"/>
        <geometry>
          <mesh filename="file://$(find panda_urdf)/meshes/collision/link1.stl"/>
        </geometry>
      </collision>
    </link>

    <!-- panda_joint1 -->
    <joint name="${prefix}panda_joint1" type="revolute">
      <origin rpy="0 0 0" xyz="0 0 0.333"/>
      <parent link="${prefix}panda_link0"/>
      <child link="${prefix}panda_link1"/>
      <axis xyz="0 0 1"/>
      <limit effort="87" lower="-2.897246558310587" upper="2.897246558310587" velocity="2.6179938779914944"/>
      <dynamics damping="21.75" friction="3.48"/>
      <!-- <safety_controller k_position="100.0" k_velocity="40.0" soft_lower_limit="-2.8973" soft_upper_limit="2.8973" /> -->
    </joint>

    <!-- panda_link2 -->
    <link name="${prefix}panda_link2">
      <inertial>
        <origin rpy="0 0 0" xyz="3.17833e-07 -0.06861 0.0322285"/>
        <mass value="2.6652755331661186"/>
        <inertia ixx="0.01778694005635383" ixy="8.70635625879119e-08" ixz="3.752072058394008e-08" iyy="0.006044133867952844" iyz="-0.004599490295490376" izz="0.01571095500455695"/>
      </inertial>
      <visual>
        <origin rpy="0 0 0" xyz="0 0 0"/>
        <geometry>
          <mesh filename="file://$(find panda_urdf)/meshes/visual/link2.dae"/>
        </geometry>
      </visual>
      <collision>
        <origin rpy="0 0 0" xyz="0 0 0"/>
        <geometry>
          <mesh filename="file://$(find panda_urdf)/meshes/collision/link2.stl"/>
        </geometry>
      </collision>
    </link>

    <!-- panda_joint2 -->
    <joint name="${prefix}panda_joint2" type="revolute">
      <origin rpy="-1.57079632679 0 0" xyz="0 0 0"/>
      <parent link="${prefix}panda_link1"/>
      <child link="${prefix}panda_link2"/>
      <axis xyz="0 0 1"/>
      <limit effort="87" lower="-1.7627825445142729" upper="1.7627825445142729" velocity="2.6179938779914944"/>
      <!-- <safety_controller k_position="100.0" k_velocity="40.0" soft_lower_limit="-1.6128" soft_upper_limit="1.6128" /> -->
      <dynamics damping="21.75" friction="3.48"/>
    </joint>

    <!-- panda_link3 -->
    <link name="${prefix}panda_link3">
      <inertial>
        <mass value="2.3293714829045733"/>
        <origin rpy="0 0 0" xyz="0.0469893 0.0316374 -0.031704"/>
        <inertia ixx="0.0075496764161139766" ixy="-0.0024320464513492225" ixz="-0.003250815048103007" iyy="0.009680676080191398" iyz="-0.0021316282421730694" izz="0.007944557422008086"/>
      </inertial>
      <visual>
        <origin rpy="0 0 0" xyz="0 0 0"/>
        <geometry>
          <mesh filename="file://$(find panda_urdf)/meshes/visual/link3.dae"/>
        </geometry>
      </visual>
      <collision>
        <origin rpy="0 0 0" xyz="0 0 0"/>
        <geometry>
          <mesh filename="file://$(find panda_urdf)/meshes/collision/link3.stl"/>
        </geometry>
      </collision>
    </link>
    <!-- panda_joint3 -->
    <joint name="${prefix}panda_joint3" type="revolute">
      <origin rpy="1.57079632679 0 0" xyz="0 -0.316 0"/>
      <parent link="${prefix}panda_link2"/>
      <child link="${prefix}panda_link3"/>
      <axis xyz="0 0 1"/>
      <limit effort="87" lower="-2.897246558310587" upper="2.897246558310587" velocity="2.6179938779914944"/>
      <!-- <safety_controller k_position="100.0" k_velocity="40.0" soft_lower_limit="-2.7473" soft_upper_limit="2.7473" /> -->
      <dynamics damping="21.75" friction="3.48"/>
    </joint>

    <!-- panda_link4-->
    <link name="${prefix}panda_link4">
      <inertial>
        <mass value="2.3104763646281508"/>
        <inertia ixx="0.007764568814864828" ixy="0.003371475204045935" ixz="-0.002343621113168248" iyy="0.008015776929980149" iyz="0.0022917526161470624" izz="0.009955882308071066"/>
        <origin rpy="0 0 0" xyz="-0.0360446 0.0336853 0.031882"/>
      </inertial>
      <visual>
        <origin rpy="0 0 0" xyz="0 0 0"/>
        <geometry>
          <mesh filename="file://$(find panda_urdf)/meshes/visual/link4.dae"/>
        </geometry>
      </visual>
      <collision>
        <origin rpy="0 0 0" xyz="0 0 0"/>
        <geometry>
          <mesh filename="file://$(find panda_urdf)/meshes/collision/link4.stl"/>
        </geometry>
      </collision>
    </link>
    <!-- panda_joint4 -->
    <joint name="${prefix}panda_joint4" type="revolute">
      <origin rpy="1.57079632679 0 0" xyz="0.0825 0 0"/>
      <parent link="${prefix}panda_link3"/>
      <child link="${prefix}panda_link4"/>
      <axis xyz="0 0 1"/>
      <!-- Upper = -0.0698131 breaks the simulation-->
      <!-- <limit effort="87" lower="-3.07177948351002" upper="-0.06981317007977318" velocity="2.6179938779914944"/> -->
      <!-- <safety_controller k_position="100.0" k_velocity="40.0" soft_lower_limit="-2.9916" soft_upper_limit="0.0627"/> -->
      <limit effort="87" lower="-3.1416" upper="0.0873" velocity="2.3925" />
      <dynamics damping="21.75" friction="3.48"/>
    </joint>

    <!-- panda_link5 -->
    <link name="${prefix}panda_link5">
      <inertial>
        <mass value="2.6226426154892004"/>
        <inertia ixx="0.029070538014399377" ixy="6.208738268725568e-07" ixz="-1.0059151925023392e-05" iyy="0.027638529986528795" iyz="-0.007424306477850814" izz="0.004251111234400737"/>
        <origin rpy="0 0 0" xyz="-6.12525e-06 0.0610427 -0.104176"/>
      </inertial>
      <visual>
        <origin rpy="0 0 0" xyz="0 0 0"/>
        <geometry>
          <mesh filename="file://$(find panda_urdf)/meshes/visual/link5.dae"/>
        </geometry>
      </visual>
      <collision>
        <origin rpy="0 0 0" xyz="0 0 0"/>
        <geometry>
          <mesh filename="file://$(find panda_urdf)/meshes/collision/link5.stl"/>
        </geometry>
      </collision>
      <!-- Added contact sensor-->
      <gazebo>
        <sensor type="contact" name="{prefix}panda_link5_contact_sensor">
          <update_rate>1000</update_rate>
          <contact>
            <collision>{prefix}panda_link5_collision</collision>
          </contact>
          <plugin name="gz_contact_plugin" filename="libgz_contact_plugin.so">
            <topic>/contact_topic_{prefix}panda_link5</topic>
          </plugin>
        </sensor>
      </gazebo>

    </link>
    <!-- panda_joint5 -->
    <joint name="panda_joint5" type="revolute">
      <origin rpy="-1.57079632679 0 0" xyz="-0.0825 0.384 0"/>
      <parent link="${prefix}panda_link4"/>
      <child link="${prefix}panda_link5"/>
      <axis xyz="0 0 1"/>
      <limit effort="12" lower="-2.897246558310587" upper="2.897246558310587" velocity="3.141592653589793"/>
      <!-- <safety_controller k_position="100.0" k_velocity="40.0" soft_lower_limit="-2.7473" soft_upper_limit="2.7473" /> -->
      <dynamics damping="3.0" friction="0.48"/>
    </joint>

    <!-- panda_link6 -->
    <link name="${prefix}panda_link6">
      <inertial>
        <origin rpy="0 0 0" xyz="0.051051 0.00910797 0.0106343"/>
        <mass value="1.5025804886626795"/>
        <inertia ixx="0.002940555801469018" ixy="-0.00042391108351381507" ixz="0.000610007735338717" iyy="0.00392105201248677" iyz="0.00012647545430836214" izz="0.0054115603870960195"/>
      </inertial>
      <visual>
        <origin rpy="0 0 0" xyz="0 0 0"/>
        <geometry>
          <mesh filename="file://$(find panda_urdf)/meshes/visual/link6.dae"/>
        </geometry>
      </visual>
      <collision>
        <origin rpy="0 0 0" xyz="0 0 0"/>
        <geometry>
          <mesh filename="file://$(find panda_urdf)/meshes/collision/link6.stl"/>
        </geometry>
      </collision>
    </link>

    <!-- panda_joint6 -->
    <joint name="${prefix}panda_joint6" type="revolute">
      <origin rpy="1.57079632679 0 0" xyz="0 0 0"/> <!-- rpy="1.57079632679 -1.57079632679 0" -->
      <parent link="${prefix}panda_link5"/>
      <child link="${prefix}panda_link6"/>
      <axis xyz="0 0 1"/>
      <limit effort="12" lower="-0.017453292519943295" upper="3.752457891787808" velocity="3.141592653589793"/>
      <!-- <safety_controller k_position="100.0" k_velocity="40.0" soft_lower_limit="-0.017453292519943295" soft_upper_limit="3.6024" /> -->
      <dynamics damping="3.0" friction="0.48"/>
    </joint>

    <!-- panda_link7 -->
    <link name="${prefix}panda_link7">
      <inertial>
        <origin rpy="0 0 0" xyz="0.0109695 0.0107965 0.0650412"/>
        <mass value="0.5237668134788256"/>
        <inertia ixx="0.0008621467959726535" ixy="-0.00011871071570425467" ixz="3.866602604509339e-05" iyy="0.0008613100184801048" iyz="-9.057841649422724e-05" izz="0.0006961139396618219"/>
      </inertial>
      <visual>
        <origin rpy="0 0 0" xyz="0 0 0"/>
        <geometry>
          <mesh filename="file://$(find panda_urdf)/meshes/visual/link7.dae"/>
        </geometry>
      </visual>
      <collision>
        <origin rpy="0 0 0" xyz="0 0 0"/>
        <geometry>
          <mesh filename="file://$(find panda_urdf)/meshes/collision/link7.stl"/>
        </geometry>
      </collision>
      
      <gazebo>
        <sensor type="contact" name="{prefix}panda_link7_contact_sensor">
          <update_rate>1000</update_rate>
          <contact>
            <collision>{prefix}panda_link7_collision</collision>
          </contact>
          <plugin name="gz_contact_plugin" filename="libgz_contact_plugin.so">
            <topic>/contact_topic_{prefix}panda_link7</topic>
          </plugin>
        </sensor>
    </gazebo>
    </link>

    <!-- panda_joint7 -->
    <joint name="${prefix}panda_joint7" type="revolute">
      <origin rpy="1.57079632679 0 0" xyz="0.088 0 0"/> <!-- rpy="1.57079632679 -0.7854 0" -->
      <parent link="${prefix}panda_link6"/>
      <child link="${prefix}panda_link7"/>
      <axis xyz="0 0 1"/>
      <limit effort="12" lower="-2.897246558310587" upper="2.897246558310587" velocity="3.141592653589793"/>
      <!-- <safety_controller k_position="100.0" k_velocity="40.0" soft_lower_limit="-2.7473" soft_upper_limit="2.7473" /> -->
      <dynamics damping="3.0" friction="0.48"/>
    </joint>

    <!-- panda_link8 -->
    <link name="${prefix}panda_link8">
    </link>

    <!-- panda_joint8 virtual -->
    <joint name="panda_link8_virtual_joint" type="fixed">
      <origin rpy="0 0 -0.7853981633974483" xyz="0 0 0.107"/>
      <parent link="${prefix}panda_link7"/>
      <child link="${prefix}panda_link8"/>
    </joint>

    <!-- panda_hand joint-->
    <joint name="${prefix}panda_hand_joint" type="fixed">
      <parent link="${prefix}panda_link8"/>
      <child link="${prefix}panda_hand"/>
      <origin rpy="0 0 0" xyz="0 0 0"/>
    </joint>

    <link name="${prefix}panda_hand">
      <inertial>
        <origin rpy="0 0 0" xyz="-6.7624e-06 0.00152435 0.0275912"/>
        <mass value="0.14060765127978503"/>
        <inertia ixx="0.0005365450414352072" ixy="1.7911952957732454e-08" ixz="-2.320071910601251e-08" iyy="7.70511954783727e-05" iyz="4.681149945315967e-08" izz="0.0004938176882694914"/>
      </inertial>
      <visual>
        <origin rpy="0 0 0" xyz="0 0 0"/>
        <geometry>
          <mesh filename="file://$(find panda_urdf)/meshes/visual/hand.dae"/>
        </geometry>
      </visual>
      <collision>
        <origin rpy="0 0 0" xyz="0 0 0"/>
        <geometry>
          <mesh filename="file://$(find panda_urdf)/meshes/collision/hand.stl"/>
        </geometry>
      </collision>
    </link>

    <!-- panda_leftfinger -->
    <link name="${prefix}panda_leftfinger">
       <inertial>
        <origin rpy="0 0 0" xyz="-6.2561e-06 0.00227781 -0.0277116"/>
        <mass value="0.2238453537819424"/>
        <inertia ixx="6.74804167363695e-05" ixy="-4.1027443646025676e-09" ixz="1.8693673970152995e-08" iyy="6.627189221641395e-05" iyz="1.1967548474390802e-05" izz="1.550396267804825e-05"/>
      </inertial>
      <visual>
        <origin rpy="0 0 0" xyz="0 0 0"/>
        <geometry>
          <mesh filename="file://$(find panda_urdf)/meshes/visual/finger.dae"/>
        </geometry>
      </visual>
      <collision>
        <origin rpy="0 0 0" xyz="0 0 0"/>
        <geometry>
          <mesh filename="file://$(find panda_urdf)/meshes/collision/finger.stl"/>
        </geometry>
      </collision>
    </link>

    <!-- panda_rightfinger -->
    <link name="${prefix}panda_rightfinger">
      <inertial>
        <origin rpy="0 0 3.141592653589793" xyz="-6.2561e-06 0.00227781 -0.0277116"/>
        <mass value="0.2238453537819424"/>
        <inertia ixx="6.74804167363695e-05" ixy="-4.1027443646025676e-09" ixz="1.8693673970152995e-08" iyy="6.627189221641395e-05" iyz="1.1967548474390802e-05" izz="1.550396267804825e-05"/>
      </inertial>
      <visual>
        <origin rpy="0 0 3.14159265359" xyz="0 0 0"/>
        <geometry>
          <mesh filename="file://$(find panda_urdf)/meshes/visual/finger.dae"/>
        </geometry>
      </visual>
      <collision name="panda_rightfinger_collision">
        <origin rpy="0 0 3.14159265359" xyz="0 0 0"/>
        <geometry>
          <mesh filename="file://$(find panda_urdf)/meshes/collision/finger.stl"/>
        </geometry>
      </collision>
    </link>

    <joint name="${prefix}panda_finger_joint1" type="prismatic">
      <parent link="${prefix}panda_hand"/>
      <child link="${prefix}panda_leftfinger"/>
      <origin rpy="0 0 0" xyz="0 0 0.0584"/>
      <axis xyz="0 1 0"/>
      <limit effort="20" lower="0" upper="0.04" velocity="0.2"/>
      <dynamics damping="3.0" friction="0.4"/>
    </joint>

    <joint name="${prefix}panda_finger_joint2" type="prismatic">
      <parent link="${prefix}panda_hand"/>
      <child link="${prefix}panda_rightfinger"/>
      <origin rpy="0 0 0" xyz="0 0 0.0584"/>
      <axis xyz="0 -1 0"/>
      <limit effort="20" lower="0" upper="0.04" velocity="0.2"/>
      <dynamics damping="3.0" friction="0.4"/>
      <!-- <mimic joint="panda_finger_joint1" /> -->
    </joint>

    <!-- End-Effector frame -->
     <link name="${prefix}panda_hand_tcp">
     </link>

    <joint name="${prefix}panda_hand_tcp_virtual_joint" type="fixed">
      <parent link="${prefix}panda_hand"/>
      <child link="${prefix}panda_hand_tcp"/>
      <origin rpy="0 0 0" xyz="0 0 0.1034"/>
    </joint>
    
 </xacro:macro>
</robot>